<?xml version="1.0" encoding="utf-8"?>
<!-- This URDF was automatically created by SolidWorks to URDF Exporter! Originally created by Stephen Brawner (brawner@gmail.com) 
     Commit Version: 1.6.0-4-g7f85cfe  Build Version: 1.6.7995.38578
     For more information, please see http://wiki.ros.org/sw_urdf_exporter -->
  <robot
    name="bionic_hand">

    <!-- World Link als neuer Root -->
  <link name="world"/>
  
  <!-- Joint um die Hand richtig zu orientieren -->
  <joint name="world_to_base" type="fixed">
    <parent link="world"/>
    <child link="base_link"/>
    <origin xyz="0 0 0" rpy="3.14159 0 0"/>  <!-- 180° um X-Achse -->
  </joint>
  
  <link
    name="base_link">
    <inertial>
      <origin
        xyz="0.03912886852115 -0.02936264886893 0.0154057797768061"
        rpy="0 0 0" />
      <mass
        value="0.648187431870064" />
      <inertia
        ixx="0.000817855553979597"
        ixy="8.875849584592E-05"
        ixz="3.31929662839044E-05"
        iyy="0.00148537892208656"
        iyz="-1.75158796634625E-05"
        izz="0.00106984032112581" />
    </inertial>
    <visual>
      <origin
        xyz="0 0 0"
        rpy="0 0 0" />
      <geometry>
        <mesh
          filename="package://hand_description/meshes/base_link.STL" />
      </geometry>
      <material
        name="">
        <color
          rgba="0.792156862745098 0.819607843137255 0.933333333333333 1" />
      </material>
    </visual>
    <collision>
      <origin
        xyz="0 0 0"
        rpy="0 0 0" />
      <geometry>
        <mesh
          filename="package://hand_description/meshes/base_link.STL" />
      </geometry>
    </collision>
  </link>
  <link
    name="thumb_opposition">
    <inertial>
      <origin
        xyz="-0.030921850566624 0.0146727324061557 -0.0164392665314555"
        rpy="0 0 0" />
      <mass
        value="0.0188289789775585" />
      <inertia
        ixx="4.45919280552344E-06"
        ixy="-5.53559993158624E-07"
        ixz="1.37851508545918E-06"
        iyy="6.98551165055523E-06"
        iyz="6.4444143928376E-07"
        izz="6.12234363761581E-06" />
    </inertial>
    <visual>
      <origin
        xyz="0 0 0"
        rpy="0 0 0" />
      <geometry>
        <mesh
          filename="package://hand_description/meshes/thumb_opposition.STL" />
      </geometry>
      <material
        name="">
        <color
          rgba="0.792156862745098 0.819607843137255 0.933333333333333 1" />
      </material>
    </visual>
    <collision>
      <origin
        xyz="0 0 0"
        rpy="0 0 0" />
      <geometry>
        <mesh
          filename="package://hand_description/meshes/thumb_opposition.STL" />
      </geometry>
    </collision>
  </link>
  <joint
    name="thumb_opposition"
    type="revolute">
    <origin
      xyz="-0.044557 -0.029225 0.0043879"
      rpy="1.1887 -0.068156 0.01342" />
    <parent
      link="base_link" />
    <child
      link="thumb_opposition" />
    <axis
      xyz="0.98363 -0.0005966 -0.18021" />
    <limit
      lower="-1.57" upper="1.57" effort="10" velocity="1"/>
  </joint>
  <link
    name="thumb_rotation">
    <inertial>
      <origin
        xyz="0.00485254318295213 0.0115774656855361 -0.0178189490794952"
        rpy="0 0 0" />
      <mass
        value="0.00899608808051006" />
      <inertia
        ixx="7.08057425667585E-07"
        ixy="1.35694118393264E-07"
        ixz="-2.45328865431087E-07"
        iyy="1.18390389757121E-06"
        iyz="1.18726868091096E-07"
        izz="1.06737398415733E-06" />
    </inertial>
    <visual>
      <origin
        xyz="0 0 0"
        rpy="0 0 0" />
      <geometry>
        <mesh
          filename="package://hand_description/meshes/thumb_rotation.STL" />
      </geometry>
      <material
        name="">
        <color
          rgba="0.792156862745098 0.819607843137255 0.933333333333333 1" />
      </material>
    </visual>
    <collision>
      <origin
        xyz="0 0 0"
        rpy="0 0 0" />
      <geometry>
        <mesh
          filename="package://hand_description/meshes/thumb_rotation.STL" />
      </geometry>
    </collision>
  </link>
  <joint
    name="thumb_rotation"
    type="revolute">
    <origin
      xyz="-0.028446 0.018239 -0.022359"
      rpy="-0.047586 0.12392 -0.19596" />
    <parent
      link="thumb_opposition" />
    <child
      link="thumb_rotation" />
    <axis
      xyz="0.1505 -0.54739 0.82323" />
    <limit
      lower="-1.57" upper="1.57" effort="10" velocity="1"/>
  </joint>
  <link
    name="thumb_mcp_flexion">
    <inertial>
      <origin
        xyz="-0.0155706608829484 0.00107315483017915 0.0062687915604831"
        rpy="0 0 0" />
      <mass
        value="0.00685716829419009" />
      <inertia
        ixx="3.11754832187612E-07"
        ixy="9.27036628856027E-08"
        ixz="6.38349944365018E-08"
        iyy="1.08304708866608E-06"
        iyz="-5.41431302860761E-09"
        izz="1.32280779786269E-06" />
    </inertial>
    <visual>
      <origin
        xyz="0 0 0"
        rpy="0 0 0" />
      <geometry>
        <mesh
          filename="package://hand_description/meshes/thumb_mcp_flexion.STL" />
      </geometry>
      <material
        name="">
        <color
          rgba="0.792156862745098 0.819607843137255 0.933333333333333 1" />
      </material>
    </visual>
    <collision>
      <origin
        xyz="0 0 0"
        rpy="0 0 0" />
      <geometry>
        <mesh
          filename="package://hand_description/meshes/thumb_mcp_flexion.STL" />
      </geometry>
    </collision>
  </link>
  <joint
    name="thumb_mcp_flexion"
    type="revolute">
    <origin
      xyz="-0.0019397 0.018317 -0.026878"
      rpy="2.1608 0.12026 0.016692" />
    <parent
      link="thumb_rotation" />
    <child
      link="thumb_mcp_flexion" />
    <axis
      xyz="0.17549 -0.00010644 0.98448" />
    <limit
      lower="-1.57" upper="1.57" effort="10" velocity="1"/>
  </joint>
  <link
    name="thumb_pip">
    <inertial>
      <origin
        xyz="-0.00718053252045824 0.000724409234434703 -0.00147454565081055"
        rpy="0 0 0" />
      <mass
        value="0.00215756681963284" />
      <inertia
        ixx="5.47658542119838E-08"
        ixy="1.88954712154763E-08"
        ixz="3.69651100914208E-08"
        iyy="2.22364898192174E-07"
        iyz="-3.41419343155599E-09"
        izz="2.52589616879644E-07" />
    </inertial>
    <visual>
      <origin
        xyz="0 0 0"
        rpy="0 0 0" />
      <geometry>
        <mesh
          filename="package://hand_description/meshes/thumb_pip.STL" />
      </geometry>
      <material
        name="">
        <color
          rgba="0.792156862745098 0.819607843137255 0.933333333333333 1" />
      </material>
    </visual>
    <collision>
      <origin
        xyz="0 0 0"
        rpy="0 0 0" />
      <geometry>
        <mesh
          filename="package://hand_description/meshes/thumb_pip.STL" />
      </geometry>
    </collision>
  </link>
  <joint
    name="thumb_pip"
    type="revolute">
    <origin
      xyz="-0.032276 0.0026768 0.0057535"
      rpy="0.017774 -0.00089913 0.099874" />
    <parent
      link="thumb_mcp_flexion" />
    <child
      link="thumb_pip" />
    <axis
      xyz="0.17549 -0.00010644 0.98448" />
    <limit
      lower="-1.57" upper="1.57" effort="10" velocity="1"/>
  </joint>
  <link
    name="thumb_dip">
    <inertial>
      <origin
        xyz="-0.00701799183672533 -0.00401755261035154 0.0040895075655876"
        rpy="0 0 0" />
      <mass
        value="0.00422718056224681" />
      <inertia
        ixx="1.40125013203282E-07"
        ixy="5.49842510113702E-09"
        ixz="9.16944340087911E-09"
        iyy="2.42391220941455E-07"
        iyz="-1.42164042694292E-08"
        izz="2.19856077912689E-07" />
    </inertial>
    <visual>
      <origin
        xyz="0 0 0"
        rpy="0 0 0" />
      <geometry>
        <mesh
          filename="package://hand_description/meshes/thumb_dip.STL" />
      </geometry>
      <material
        name="">
        <color
          rgba="0.792156862745098 0.819607843137255 0.933333333333333 1" />
      </material>
    </visual>
    <collision>
      <origin
        xyz="0 0 0"
        rpy="0 0 0" />
      <geometry>
        <mesh
          filename="package://hand_description/meshes/thumb_dip.STL" />
      </geometry>
    </collision>
  </link>
  <joint
    name="thumb_dip"
    type="revolute">
    <origin
      xyz="-0.024063 0.0027904 0.0042895"
      rpy="-0.00063934 0 -0.0035867" />
    <parent
      link="thumb_pip" />
    <child
      link="thumb_dip" />
    <axis
      xyz="0.17549 -0.00010644 0.98448" />
    <limit
      lower="-1.57" upper="1.57" effort="10" velocity="1"/>
  </joint>
  <link
    name="index_mcp_adduction">
    <inertial>
      <origin
        xyz="-0.000909442206088804 0.0190949661941328 0.00490966953133031"
        rpy="0 0 0" />
      <mass
        value="0.00962689371201742" />
      <inertia
        ixx="3.02649913257995E-06"
        ixy="3.09387520209351E-08"
        ixz="-6.74558178094872E-08"
        iyy="1.661110752292E-06"
        iyz="-4.11033806607042E-08"
        izz="1.78272744485798E-06" />
    </inertial>
    <visual>
      <origin
        xyz="0 0 0"
        rpy="0 0 0" />
      <geometry>
        <mesh
          filename="package://hand_description/meshes/index_mcp_adduction.STL" />
      </geometry>
      <material
        name="">
        <color
          rgba="0.792156862745098 0.819607843137255 0.933333333333333 1" />
      </material>
    </visual>
    <collision>
      <origin
        xyz="0 0 0"
        rpy="0 0 0" />
      <geometry>
        <mesh
          filename="package://hand_description/meshes/index_mcp_adduction.STL" />
      </geometry>
    </collision>
  </link>
  <joint
    name="index_mcp_adduction"
    type="revolute">
    <origin
      xyz="-0.12274 -0.01291 0.0017357"
      rpy="0.0040501 -0.1746 1.7321" />
    <parent
      link="base_link" />
    <child
      link="index_mcp_adduction" />
    <axis
      xyz="0 0 1" />
    <limit
      lower="-1.57" upper="1.57" effort="10" velocity="1"/>
  </joint>
  <link
    name="index_mcp_flexion">
    <inertial>
      <origin
        xyz="-0.0154275004042288 0.00100778126665387 0.00624318904258513"
        rpy="0 0 0" />
      <mass
        value="0.00685716890077463" />
      <inertia
        ixx="3.11754917857904E-07"
        ixy="9.27038189150363E-08"
        ixz="6.38350382574896E-08"
        iyy="1.08304723128294E-06"
        iyz="-5.4143397273879E-09"
        izz="1.32280803769048E-06" />
    </inertial>
    <visual>
      <origin
        xyz="0 0 0"
        rpy="0 0 0" />
      <geometry>
        <mesh
          filename="package://hand_description/meshes/index_mcp_flexion.STL" />
      </geometry>
      <material
        name="">
        <color
          rgba="0.792156862745098 0.819607843137255 0.933333333333333 1" />
      </material>
    </visual>
    <collision>
      <origin
        xyz="0 0 0"
        rpy="0 0 0" />
      <geometry>
        <mesh
          filename="package://hand_description/meshes/index_mcp_flexion.STL" />
      </geometry>
    </collision>
  </link>
  <joint
    name="index_mcp_flexion"
    type="revolute">
    <origin
      xyz="0 0.035216 0.0089673"
      rpy="1.578 -0.040815 -1.7473" />
    <parent
      link="index_mcp_adduction" />
    <child
      link="index_mcp_flexion" />
    <axis
      xyz="0.17549 -0.00010644 0.98448" />
    <limit
      lower="-1.57" upper="1.57" effort="10" velocity="1"/>
  </joint>
  <link
    name="index_pip">
    <inertial>
      <origin
        xyz="-0.00718054768711812 0.000724415491161829 -0.00147461646332276"
        rpy="0 0 0" />
      <mass
        value="0.0021575700735159" />
      <inertia
        ixx="5.47658929498861E-08"
        ixy="1.88954712154763E-08"
        ixz="3.69651213830989E-08"
        iyy="2.22364898660454E-07"
        iyz="-3.41421563770417E-09"
        izz="2.52589630171238E-07" />
    </inertial>
    <visual>
      <origin
        xyz="0 0 0"
        rpy="0 0 0" />
      <geometry>
        <mesh
          filename="package://hand_description/meshes/index_pip.STL" />
      </geometry>
      <material
        name="">
        <color
          rgba="0.792156862745098 0.819607843137255 0.933333333333333 1" />
      </material>
    </visual>
    <collision>
      <origin
        xyz="0 0 0"
        rpy="0 0 0" />
      <geometry>
        <mesh
          filename="package://hand_description/meshes/index_pip.STL" />
      </geometry>
    </collision>
  </link>
  <joint
    name="index_pip"
    type="revolute">
    <origin
      xyz="-0.032133 0.0026114 0.005728"
      rpy="0.0034307 -3.5099E-05 0.019248" />
    <parent
      link="index_mcp_flexion" />
    <child
      link="index_pip" />
    <axis
      xyz="0.17549 -0.00010644 0.98448" />
    <limit
      lower="-1.57" upper="1.57" effort="10" velocity="1"/>
  </joint>
  <link
    name="index_dip">
    <inertial>
      <origin
        xyz="-0.00701801050887174 -0.00401756413081353 0.00408943386267118"
        rpy="0 0 0" />
      <mass
        value="0.00422718985712478" />
      <inertia
        ixx="1.40125332609245E-07"
        ixy="5.4989434339799E-09"
        ixz="9.16944340087911E-09"
        iyy="2.42391220941455E-07"
        iyz="-1.42164042694292E-08"
        izz="2.19856077912689E-07" />
    </inertial>
    <visual>
      <origin
        xyz="0 0 0"
        rpy="0 0 0" />
      <geometry>
        <mesh
          filename="package://hand_description/meshes/index_dip.STL" />
      </geometry>
      <material
        name="">
        <color
          rgba="0.792156862745098 0.819607843137255 0.933333333333333 1" />
      </material>
    </visual>
    <collision>
      <origin
        xyz="0 0 0"
        rpy="0 0 0" />
      <geometry>
        <mesh
          filename="package://hand_description/meshes/index_dip.STL" />
      </geometry>
    </collision>
  </link>
  <joint
    name="index_dip"
    type="revolute">
    <origin
      xyz="-0.024063 0.0027904 0.0042895"
      rpy="-4.2835E-05 0 -0.0002403" />
    <parent
      link="index_pip" />
    <child
      link="index_dip" />
    <axis
      xyz="0.17549 -0.00010644 0.98448" />
    <limit
      lower="-1.57" upper="1.57" effort="10" velocity="1"/>
  </joint>
  <link
    name="middle_mcp_adduction">
    <inertial>
      <origin
        xyz="-0.000909456160867496 0.0190949655020067 0.00383527933159585"
        rpy="0 0 0" />
      <mass
        value="0.00962699091217545" />
      <inertia
        ixx="3.02651450369156E-06"
        ixy="3.09366445016753E-08"
        ixz="-6.7455127807663E-08"
        iyy="1.66112636596979E-06"
        iyz="-4.11040110353174E-08"
        izz="1.78272765289441E-06" />
    </inertial>
    <visual>
      <origin
        xyz="0 0 0"
        rpy="0 0 0" />
      <geometry>
        <mesh
          filename="package://hand_description/meshes/middle_mcp_adduction.STL" />
      </geometry>
      <material
        name="">
        <color
          rgba="0.792156862745098 0.819607843137255 0.933333333333333 1" />
      </material>
    </visual>
    <collision>
      <origin
        xyz="0 0 0"
        rpy="0 0 0" />
      <geometry>
        <mesh
          filename="package://hand_description/meshes/middle_mcp_adduction.STL" />
      </geometry>
    </collision>
  </link>
  <joint
    name="middle_mcp_adduction"
    type="revolute">
    <origin
      xyz="-0.11711 -0.043668 7.1028E-05"
      rpy="0.00059664 -0.00010907 1.7516" />
    <parent
      link="base_link" />
    <child
      link="middle_mcp_adduction" />
    <axis
      xyz="0 0 1" />
    <limit
      lower="-1.57" upper="1.57" effort="10" velocity="1"/>
  </joint>
  <link
    name="middle_mcp_flexion">
    <inertial>
      <origin
        xyz="-0.0154275030022819 0.00100778200353721 0.00624318994442184"
        rpy="0 0 0" />
      <mass
        value="0.0068571698643642" />
      <inertia
        ixx="3.11754879603603E-07"
        ixy="9.27036352232273E-08"
        ixz="6.38349892593742E-08"
        iyy="1.08304714144964E-06"
        iyz="-5.41430447712902E-09"
        izz="1.32280788660599E-06" />
    </inertial>
    <visual>
      <origin
        xyz="0 0 0"
        rpy="0 0 0" />
      <geometry>
        <mesh
          filename="package://hand_description/meshes/middle_mcp_flexion.STL" />
      </geometry>
      <material
        name="">
        <color
          rgba="0.792156862745098 0.819607843137255 0.933333333333333 1" />
      </material>
    </visual>
    <collision>
      <origin
        xyz="0 0 0"
        rpy="0 0 0" />
      <geometry>
        <mesh
          filename="package://hand_description/meshes/middle_mcp_flexion.STL" />
      </geometry>
    </collision>
  </link>
  <joint
    name="middle_mcp_flexion"
    type="revolute">
    <origin
      xyz="0 0.035216 0.0078927"
      rpy="1.5802 -0.053034 -1.7474" />
    <parent
      link="middle_mcp_adduction" />
    <child
      link="middle_mcp_flexion" />
    <axis
      xyz="0.17549 -0.00010644 0.98448" />
    <limit
      lower="-1.57" upper="1.57" effort="10" velocity="1"/>
  </joint>
  <link
    name="middle_pip">
    <inertial>
      <origin
        xyz="-0.00718054709055196 0.000724413459740089 -0.00147461630101051"
        rpy="0 0 0" />
      <mass
        value="0.00215756882872642" />
      <inertia
        ixx="5.4765889602427E-08"
        ixy="1.8895496022229E-08"
        ixz="3.69651226560766E-08"
        iyy="2.22364893977912E-07"
        iyz="-3.41420959985044E-09"
        izz="2.52589615008745E-07" />
    </inertial>
    <visual>
      <origin
        xyz="0 0 0"
        rpy="0 0 0" />
      <geometry>
        <mesh
          filename="package://hand_description/meshes/middle_pip.STL" />
      </geometry>
      <material
        name="">
        <color
          rgba="0.792156862745098 0.819607843137255 0.933333333333333 1" />
      </material>
    </visual>
    <collision>
      <origin
        xyz="0 0 0"
        rpy="0 0 0" />
      <geometry>
        <mesh
          filename="package://hand_description/meshes/middle_pip.STL" />
      </geometry>
    </collision>
  </link>
  <joint
    name="middle_pip"
    type="revolute">
    <origin
      xyz="-0.032133 0.0026114 0.005728"
      rpy="-0.015853 -0.00069671 -0.08905" />
    <parent
      link="middle_mcp_flexion" />
    <child
      link="middle_pip" />
    <axis
      xyz="0.17549 -0.00010644 0.98448" />
    <limit
      lower="-1.57" upper="1.57" effort="10" velocity="1"/>
  </joint>
  <link
    name="middle_dip">
    <inertial>
      <origin
        xyz="-0.0070180041181831 -0.00401755227750198 0.00408943482244931"
        rpy="0 0 0" />
      <mass
        value="0.00422718330911699" />
      <inertia
        ixx="1.40125253311056E-07"
        ixy="5.49855152148082E-09"
        ixz="9.16944340087911E-09"
        iyy="2.42391220941455E-07"
        iyz="-1.42164042694292E-08"
        izz="2.19856077912689E-07" />
    </inertial>
    <visual>
      <origin
        xyz="0 0 0"
        rpy="0 0 0" />
      <geometry>
        <mesh
          filename="package://hand_description/meshes/middle_dip.STL" />
      </geometry>
      <material
        name="">
        <color
          rgba="0.792156862745098 0.819607843137255 0.933333333333333 1" />
      </material>
    </visual>
    <collision>
      <origin
        xyz="0 0 0"
        rpy="0 0 0" />
      <geometry>
        <mesh
          filename="package://hand_description/meshes/middle_dip.STL" />
      </geometry>
    </collision>
  </link>
  <joint
    name="middle_dip"
    type="revolute">
    <origin
      xyz="-0.024063 0.0027904 0.0042895"
      rpy="0 0 -1.4192E-05" />
    <parent
      link="middle_pip" />
    <child
      link="middle_dip" />
    <axis
      xyz="0.17549 -0.00010644 0.98448" />
    <limit
      lower="-1.57" upper="1.57" effort="10" velocity="1"/>
  </joint>
  <link
    name="ring_mcp_adduction">
    <inertial>
      <origin
        xyz="-0.000909455864437692 0.0190949613934563 -0.00267839039401092"
        rpy="0 0 0" />
      <mass
        value="0.00962693787838278" />
      <inertia
        ixx="3.0265048625789E-06"
        ixy="3.09370182370882E-08"
        ixz="-6.74553882496884E-08"
        iyy="1.66111638568848E-06"
        iyz="-4.11044555814314E-08"
        izz="1.78272762164739E-06" />
    </inertial>
    <visual>
      <origin
        xyz="0 0 0"
        rpy="0 0 0" />
      <geometry>
        <mesh
          filename="package://hand_description/meshes/ring_mcp_adduction.STL" />
      </geometry>
      <material
        name="">
        <color
          rgba="0.792156862745098 0.819607843137255 0.933333333333333 1" />
      </material>
    </visual>
    <collision>
      <origin
        xyz="0 0 0"
        rpy="0 0 0" />
      <geometry>
        <mesh
          filename="package://hand_description/meshes/ring_mcp_adduction.STL" />
      </geometry>
    </collision>
  </link>
  <joint
    name="ring_mcp_adduction"
    type="revolute">
    <origin
      xyz="-0.1117 -0.073131 0.0092019"
      rpy="0.0022405 0.17441 1.7615" />
    <parent
      link="base_link" />
    <child
      link="ring_mcp_adduction" />
    <axis
      xyz="0 0 1" />
    <limit
      lower="-1.57" upper="1.57" effort="10" velocity="1"/>
  </joint>
  <link
    name="ring_mcp_flexion">
    <inertial>
      <origin
        xyz="-0.0154275034191903 0.00100778086195735 0.00624318989506015"
        rpy="0 0 0" />
      <mass
        value="0.00685717323720477" />
      <inertia
        ixx="3.11755007536061E-07"
        ixy="9.27037264782968E-08"
        ixz="6.38349855975595E-08"
        iyy="1.08304731854444E-06"
        iyz="-5.41433853598548E-09"
        izz="1.32280819118396E-06" />
    </inertial>
    <visual>
      <origin
        xyz="0 0 0"
        rpy="0 0 0" />
      <geometry>
        <mesh
          filename="package://hand_description/meshes/ring_mcp_flexion.STL" />
      </geometry>
      <material
        name="">
        <color
          rgba="0.792156862745098 0.819607843137255 0.933333333333333 1" />
      </material>
    </visual>
    <collision>
      <origin
        xyz="0 0 0"
        rpy="0 0 0" />
      <geometry>
        <mesh
          filename="package://hand_description/meshes/ring_mcp_flexion.STL" />
      </geometry>
    </collision>
  </link>
  <joint
    name="ring_mcp_flexion"
    type="revolute">
    <origin
      xyz="0 0.035216 0.0013791"
      rpy="1.5766 -0.033102 -1.7473" />
    <parent
      link="ring_mcp_adduction" />
    <child
      link="ring_mcp_flexion" />
    <axis
      xyz="0.17549 -0.00010644 0.98448" />
    <limit
      lower="-1.57" upper="1.57" effort="10" velocity="1"/>
  </joint>
  <link
    name="ring_pip">
    <inertial>
      <origin
        xyz="-0.00718054880538105 0.000724418427504727 -0.0014746151518933"
        rpy="0 0 0" />
      <mass
        value="0.0021575716166911" />
      <inertia
        ixx="5.47659092325574E-08"
        ixy="1.88954922723444E-08"
        ixz="3.6965124205342E-08"
        iyy="2.22364893977912E-07"
        iyz="-3.41420959985044E-09"
        izz="2.52589615008745E-07" />
    </inertial>
    <visual>
      <origin
        xyz="0 0 0"
        rpy="0 0 0" />
      <geometry>
        <mesh
          filename="package://hand_description/meshes/ring_pip.STL" />
      </geometry>
      <material
        name="">
        <color
          rgba="0.792156862745098 0.819607843137255 0.933333333333333 1" />
      </material>
    </visual>
    <collision>
      <origin
        xyz="0 0 0"
        rpy="0 0 0" />
      <geometry>
        <mesh
          filename="package://hand_description/meshes/ring_pip.STL" />
      </geometry>
    </collision>
  </link>
  <joint
    name="ring_pip"
    type="revolute">
    <origin
      xyz="-0.032133 0.0026114 0.005728"
      rpy="0.0044873 -5.9213E-05 0.025177" />
    <parent
      link="ring_mcp_flexion" />
    <child
      link="ring_pip" />
    <axis
      xyz="0.17549 -0.00010644 0.98448" />
    <limit
      lower="-1.57" upper="1.57" effort="10" velocity="1"/>
  </joint>
  <link
    name="ring_dip">
    <inertial>
      <origin
        xyz="-0.00701800898049987 -0.00401756854863062 0.00408943428993482"
        rpy="0 0 0" />
      <mass
        value="0.00422719118859117" />
      <inertia
        ixx="1.40125386130337E-07"
        ixy="5.49920582744171E-09"
        ixz="9.16976614596534E-09"
        iyy="2.42392426432486E-07"
        iyz="-1.42164439566301E-08"
        izz="2.19857467650712E-07" />
    </inertial>
    <visual>
      <origin
        xyz="0 0 0"
        rpy="0 0 0" />
      <geometry>
        <mesh
          filename="package://hand_description/meshes/ring_dip.STL" />
      </geometry>
      <material
        name="">
        <color
          rgba="0.792156862745098 0.819607843137255 0.933333333333333 1" />
      </material>
    </visual>
    <collision>
      <origin
        xyz="0 0 0"
        rpy="0 0 0" />
      <geometry>
        <mesh
          filename="package://hand_description/meshes/ring_dip.STL" />
      </geometry>
    </collision>
  </link>
  <joint
    name="ring_dip"
    type="revolute">
    <origin
      xyz="-0.024063 0.0027904 0.0042895"
      rpy="-6.3764E-05 0 -0.00035772" />
    <parent
      link="ring_pip" />
    <child
      link="ring_dip" />
    <axis
      xyz="0.17549 -0.00010644 0.98448" />
    <limit
      lower="-1.57" upper="1.57" effort="10" velocity="1"/>
  </joint>
</robot>